<?xml version="1.0" encoding="utf-8"?>
<!-- =================================================================================== -->
<!-- |    This document was autogenerated by xacro from quad_sim.xacro                 | -->
<!-- |    EDITING THIS FILE BY HAND IS NOT RECOMMENDED                                 | -->
<!-- =================================================================================== -->
<robot name="quadrotor/quadrotor">
  <link name="frame">
    <inertial>
      <mass value="0.061399"/>
      <origin rpy="0 0 0" xyz="-0.11 0.11 0"/>
      <inertia ixx="1.231E-04" ixy="-3.560E-08" ixz="4.131E-07" iyy="1.218E-04" iyz="4.210E-07" izz="1.942E-04"/>
    </inertial>
    <visual>
      <origin rpy="1.57079632679 0 0" xyz="-0.11 0.11 0"/>
      <geometry>
        <mesh filename="/home/nptttn/senior_project/quad_sim/src/quad_sim/urdf/meshes/final_frame.stl" scale="0.001 0.001 0.001"/>
      </geometry>
    </visual>
    <collision>
      <origin rpy="1.57079632679 0 0" xyz="-0.11 0.11 0"/>
      <geometry>
        <mesh filename="/home/nptttn/senior_project/quad_sim/src/quad_sim/urdf/meshes/final_frame.stl" scale="0.001 0.001 0.001"/>
      </geometry>
    </collision>
  </link>
  <link name="propeller_holder1">
    <inertial>
      <mass value="0.01696"/>
      <origin rpy="0 0 0" xyz="0 0 0"/>
      <inertia ixx="0.00" ixy="0.00" ixz="0.00" iyy="0.00" iyz="0.00" izz="0.00"/>
    </inertial>
    <visual>
      <origin rpy="0 0 0" xyz="0 0 0"/>
      <geometry>
        <mesh filename="/home/nptttn/senior_project/quad_sim/src/quad_sim/urdf/meshes/KV2540_Motor_Base.stl" scale="0.001 0.001 0.001"/>
      </geometry>
    </visual>
    <collision>
      <origin rpy="0 0 0" xyz="0 0 0"/>
      <geometry>
        <mesh filename="/home/nptttn/senior_project/quad_sim/src/quad_sim/urdf/meshes/KV2540_Motor_Base.stl" scale="0.001 0.001 0.001"/>
      </geometry>
    </collision>
  </link>
  <joint name="body_propeller1" type="fixed">
    <origin rpy="1.57079632679 0 0" xyz="0.095 -0.095 0.08"/>
    <parent link="frame"/>
    <child link="propeller_holder1"/>
  </joint>
  <link name="propeller_holder2">
    <inertial>
      <mass value="0.01696"/>
      <origin rpy="0 0 0" xyz="0 0 0"/>
      <inertia ixx="0.00" ixy="0.00" ixz="0.00" iyy="0.00" iyz="0.00" izz="0.00"/>
    </inertial>
    <visual>
      <origin rpy="0 0 0" xyz="0 0 0"/>
      <geometry>
        <mesh filename="/home/nptttn/senior_project/quad_sim/src/quad_sim/urdf/meshes/KV2540_Motor_Base.stl" scale="0.001 0.001 0.001"/>
      </geometry>
    </visual>
    <collision>
      <origin rpy="0 0 0" xyz="0 0 0"/>
      <geometry>
        <mesh filename="/home/nptttn/senior_project/quad_sim/src/quad_sim/urdf/meshes/KV2540_Motor_Base.stl" scale="0.001 0.001 0.001"/>
      </geometry>
    </collision>
  </link>
  <joint name="body_propeller2" type="fixed">
    <origin rpy="1.57079632679 0 0" xyz="-0.095 0.095 0.08"/>
    <parent link="frame"/>
    <child link="propeller_holder2"/>
  </joint>
  <link name="propeller_holder3">
    <inertial>
      <mass value="0.01696"/>
      <origin rpy="0 0 0" xyz="0 0 0"/>
      <inertia ixx="0.00" ixy="0.00" ixz="0.00" iyy="0.00" iyz="0.00" izz="0.00"/>
    </inertial>
    <visual>
      <origin rpy="0 0 0" xyz="0 0 0"/>
      <geometry>
        <mesh filename="/home/nptttn/senior_project/quad_sim/src/quad_sim/urdf/meshes/KV2540_Motor_Base.stl" scale="0.001 0.001 0.001"/>
      </geometry>
    </visual>
    <collision>
      <origin rpy="0 0 0" xyz="0 0 0"/>
      <geometry>
        <mesh filename="/home/nptttn/senior_project/quad_sim/src/quad_sim/urdf/meshes/KV2540_Motor_Base.stl" scale="0.001 0.001 0.001"/>
      </geometry>
    </collision>
  </link>
  <joint name="body_propeller3" type="fixed">
    <origin rpy="1.57079632679 0 0" xyz="0.095 0.095 0.08"/>
    <parent link="frame"/>
    <child link="propeller_holder3"/>
  </joint>
  <link name="propeller_holder4">
    <inertial>
      <mass value="0.01696"/>
      <origin rpy="0 0 0" xyz="0 0 0"/>
      <inertia ixx="0.00" ixy="0.00" ixz="0.00" iyy="0.00" iyz="0.00" izz="0.00"/>
    </inertial>
    <visual>
      <origin rpy="0 0 0" xyz="0 0 0"/>
      <geometry>
        <mesh filename="/home/nptttn/senior_project/quad_sim/src/quad_sim/urdf/meshes/KV2540_Motor_Base.stl" scale="0.001 0.001 0.001"/>
      </geometry>
    </visual>
    <collision>
      <origin rpy="0 0 0" xyz="0 0 0"/>
      <geometry>
        <mesh filename="/home/nptttn/senior_project/quad_sim/src/quad_sim/urdf/meshes/KV2540_Motor_Base.stl" scale="0.001 0.001 0.001"/>
      </geometry>
    </collision>
  </link>
  <joint name="body_propeller4" type="fixed">
    <origin rpy="1.57079632679 0 0" xyz="-0.095 -0.095 0.08"/>
    <parent link="frame"/>
    <child link="propeller_holder4"/>
  </joint>
  <link name="propeller1">
    <inertial>
      <mass value="0.01696"/>
      <origin rpy="0 0 0" xyz="0 0 0"/>
      <inertia ixx="3.962E-06" ixy="0.00" ixz="-8.233E-10" iyy="6.100E-06" iyz="0.00" izz="6.716E-06"/>
    </inertial>
    <visual>
      <origin rpy="0 0 0" xyz="0 0 0"/>
      <geometry>
        <mesh filename="/home/nptttn/senior_project/quad_sim/src/quad_sim/urdf/meshes/KV2540_Motor_Propeller_holder.stl" scale="0.001 0.001 0.001"/>
      </geometry>
    </visual>
    <collision>
      <origin rpy="0 0 0" xyz="0 0 0"/>
      <geometry>
        <mesh filename="/home/nptttn/senior_project/quad_sim/src/quad_sim/urdf/meshes/KV2540_Motor_Propeller_holder.stl" scale="0.001 0.001 0.001"/>
      </geometry>
    </collision>
  </link>
  <joint name="propeller_base_propeller1" type="continuous">
    <origin rpy="1.57079632679 0 0" xyz="0.095 -0.095 0.081"/>
    <parent link="frame"/>
    <child link="propeller1"/>
    <axis xyz="0 1 0"/>
    <dynamics damping="0.0004" friction="0.00"/>
  </joint>
  <link name="propeller2">
    <inertial>
      <mass value="0.01696"/>
      <origin rpy="0 0 0" xyz="0 0 0"/>
      <inertia ixx="3.962E-06" ixy="0.00" ixz="-8.233E-10" iyy="6.100E-06" iyz="0.00" izz="6.716E-06"/>
    </inertial>
    <visual>
      <origin rpy="0 0 0" xyz="0 0 0"/>
      <geometry>
        <mesh filename="/home/nptttn/senior_project/quad_sim/src/quad_sim/urdf/meshes/KV2540_Motor_Propeller_holder.stl" scale="0.001 0.001 0.001"/>
      </geometry>
    </visual>
    <collision>
      <origin rpy="0 0 0" xyz="0 0 0"/>
      <geometry>
        <mesh filename="/home/nptttn/senior_project/quad_sim/src/quad_sim/urdf/meshes/KV2540_Motor_Propeller_holder.stl" scale="0.001 0.001 0.001"/>
      </geometry>
    </collision>
  </link>
  <joint name="propeller_base_propeller2" type="continuous">
    <origin rpy="1.57079632679 0 0" xyz="-0.095 0.095 0.081"/>
    <parent link="frame"/>
    <child link="propeller2"/>
    <axis xyz="0 1 0"/>
    <dynamics damping="0.0004" friction="0.00"/>
  </joint>
  <link name="propeller3">
    <inertial>
      <mass value="0.01696"/>
      <origin rpy="0 0 0" xyz="0 0 0"/>
      <inertia ixx="3.962E-06" ixy="0.00" ixz="-8.233E-10" iyy="6.100E-06" iyz="0.00" izz="6.716E-06"/>
    </inertial>
    <visual>
      <origin rpy="0 0 0" xyz="0 0 0"/>
      <geometry>
        <mesh filename="/home/nptttn/senior_project/quad_sim/src/quad_sim/urdf/meshes/KV2540_Motor_Propeller_holder.stl" scale="0.001 0.001 0.001"/>
      </geometry>
    </visual>
    <collision>
      <origin rpy="0 0 0" xyz="0 0 0"/>
      <geometry>
        <mesh filename="/home/nptttn/senior_project/quad_sim/src/quad_sim/urdf/meshes/KV2540_Motor_Propeller_holder.stl" scale="0.001 0.001 0.001"/>
      </geometry>
    </collision>
  </link>
  
1
    
  <joint name="propeller_base_propeller3" type="continuous">
    <origin rpy="1.57079632679 0 0" xyz="0.095 0.095 0.081"/>
    <parent link="frame"/>
    <child link="propeller3"/>
    <axis xyz="0 1 0"/>
    <dynamics damping="0.0004" friction="0.00"/>
  </joint>
  <link name="propeller4">
    <inertial>
      <mass value="0.01696"/>
      <origin rpy="0 0 0" xyz="0 0 0"/>
      <inertia ixx="3.962E-06" ixy="0.00" ixz="-8.233E-10" iyy="6.100E-06" iyz="0.00" izz="6.716E-06"/>
    </inertial>
    <visual>
      <origin rpy="0 0 0" xyz="0 0 0"/>
      <geometry>
        <mesh filename="/home/nptttn/senior_project/quad_sim/src/quad_sim/urdf/meshes/KV2540_Motor_Propeller_holder.stl" scale="0.001 0.001 0.001"/>
      </geometry>
    </visual>
    <collision>
      <origin rpy="0 0 0" xyz="0 0 0"/>
      <geometry>
        <mesh filename="/home/nptttn/senior_project/quad_sim/src/quad_sim/urdf/meshes/KV2540_Motor_Propeller_holder.stl" scale="0.001 0.001 0.001"/>
      </geometry>
    </collision>
  </link>
  <joint name="propeller_base_propeller4" type="continuous">
    <origin rpy="1.57079632679 0 0" xyz="-0.095 -0.095 0.081"/>
    <parent link="frame"/>
    <child link="propeller4"/>
    <axis xyz="0 1 0"/>
    <dynamics damping="0.0004" friction="0.00"/>
  </joint>
  <gazebo>
    <plugin filename="libquad_liftforce_plugins.so" name="quad_liftforce_plugins">
      <robotNamespace>quad_sim</robotNamespace>
      <propeller1_link>propeller1</propeller1_link>
      <propeller2_link>propeller2</propeller2_link>
      <propeller3_link>propeller3</propeller3_link>
      <propeller4_link>propeller4</propeller4_link>
      <topicName>throttle</topicName>
    </plugin>
  </gazebo>
</robot>

